2020-08-18 22:28:48,435 ERROR: Exception on /user/Emily [GET] [in C:\Users\Christopher\miniconda3\envs\py37\lib\site-packages\flask\app.py:1892]
Traceback (most recent call last):
  File "C:\Users\Christopher\miniconda3\envs\py37\lib\site-packages\flask\app.py", line 2447, in wsgi_app
    response = self.full_dispatch_request()
  File "C:\Users\Christopher\miniconda3\envs\py37\lib\site-packages\flask\app.py", line 1952, in full_dispatch_request
    rv = self.handle_user_exception(e)
  File "C:\Users\Christopher\miniconda3\envs\py37\lib\site-packages\flask\app.py", line 1821, in handle_user_exception
    reraise(exc_type, exc_value, tb)
  File "C:\Users\Christopher\miniconda3\envs\py37\lib\site-packages\flask\_compat.py", line 39, in reraise
    raise value
  File "C:\Users\Christopher\miniconda3\envs\py37\lib\site-packages\flask\app.py", line 1950, in full_dispatch_request
    rv = self.dispatch_request()
  File "C:\Users\Christopher\miniconda3\envs\py37\lib\site-packages\flask\app.py", line 1936, in dispatch_request
    return self.view_functions[rule.endpoint](**req.view_args)
  File "C:\Users\Christopher\miniconda3\envs\py37\lib\site-packages\flask_login\utils.py", line 272, in decorated_view
    return func(*args, **kwargs)
  File "C:\Users\Christopher\Documents\python\app\routes.py", line 127, in user
    form = EmptyForm()
NameError: name 'EmptyForm' is not defined
2020-08-18 22:28:56,273 ERROR: Exception on /user/Mike [GET] [in C:\Users\Christopher\miniconda3\envs\py37\lib\site-packages\flask\app.py:1892]
Traceback (most recent call last):
  File "C:\Users\Christopher\miniconda3\envs\py37\lib\site-packages\flask\app.py", line 2447, in wsgi_app
    response = self.full_dispatch_request()
  File "C:\Users\Christopher\miniconda3\envs\py37\lib\site-packages\flask\app.py", line 1952, in full_dispatch_request
    rv = self.handle_user_exception(e)
  File "C:\Users\Christopher\miniconda3\envs\py37\lib\site-packages\flask\app.py", line 1821, in handle_user_exception
    reraise(exc_type, exc_value, tb)
  File "C:\Users\Christopher\miniconda3\envs\py37\lib\site-packages\flask\_compat.py", line 39, in reraise
    raise value
  File "C:\Users\Christopher\miniconda3\envs\py37\lib\site-packages\flask\app.py", line 1950, in full_dispatch_request
    rv = self.dispatch_request()
  File "C:\Users\Christopher\miniconda3\envs\py37\lib\site-packages\flask\app.py", line 1936, in dispatch_request
    return self.view_functions[rule.endpoint](**req.view_args)
  File "C:\Users\Christopher\miniconda3\envs\py37\lib\site-packages\flask_login\utils.py", line 272, in decorated_view
    return func(*args, **kwargs)
  File "C:\Users\Christopher\Documents\python\app\routes.py", line 127, in user
    form = EmptyForm()
NameError: name 'EmptyForm' is not defined
2020-08-18 22:29:02,060 ERROR: Exception on /user/Christopher [GET] [in C:\Users\Christopher\miniconda3\envs\py37\lib\site-packages\flask\app.py:1892]
Traceback (most recent call last):
  File "C:\Users\Christopher\miniconda3\envs\py37\lib\site-packages\flask\app.py", line 2447, in wsgi_app
    response = self.full_dispatch_request()
  File "C:\Users\Christopher\miniconda3\envs\py37\lib\site-packages\flask\app.py", line 1952, in full_dispatch_request
    rv = self.handle_user_exception(e)
  File "C:\Users\Christopher\miniconda3\envs\py37\lib\site-packages\flask\app.py", line 1821, in handle_user_exception
    reraise(exc_type, exc_value, tb)
  File "C:\Users\Christopher\miniconda3\envs\py37\lib\site-packages\flask\_compat.py", line 39, in reraise
    raise value
  File "C:\Users\Christopher\miniconda3\envs\py37\lib\site-packages\flask\app.py", line 1950, in full_dispatch_request
    rv = self.dispatch_request()
  File "C:\Users\Christopher\miniconda3\envs\py37\lib\site-packages\flask\app.py", line 1936, in dispatch_request
    return self.view_functions[rule.endpoint](**req.view_args)
  File "C:\Users\Christopher\miniconda3\envs\py37\lib\site-packages\flask_login\utils.py", line 272, in decorated_view
    return func(*args, **kwargs)
  File "C:\Users\Christopher\Documents\python\app\routes.py", line 127, in user
    form = EmptyForm()
NameError: name 'EmptyForm' is not defined
2020-08-18 22:30:26,151 INFO: RecommenDev startup [in C:\Users\Christopher\Documents\python\app\__init__.py:34]
2020-08-19 09:56:03,325 INFO: RecommenDev startup [in C:\Users\Christopher\Documents\python\app\__init__.py:34]
2020-08-19 10:14:59,212 INFO: RecommenDev startup [in C:\Users\Christopher\Documents\python\app\__init__.py:34]
2020-08-19 10:16:50,933 INFO: RecommenDev startup [in C:\Users\Christopher\Documents\python\app\__init__.py:34]
2020-08-19 10:25:41,231 INFO: RecommenDev startup [in C:\Users\Christopher\Documents\python\app\__init__.py:34]
2020-08-19 11:10:20,692 INFO: RecommenDev startup [in C:\Users\Christopher\Documents\python\app\__init__.py:37]
2020-08-19 11:14:52,747 INFO: RecommenDev startup [in C:\Users\Christopher\Documents\python\app\__init__.py:37]
2020-08-19 11:18:14,463 INFO: RecommenDev startup [in C:\Users\Christopher\Documents\python\app\__init__.py:37]
2020-08-19 11:23:05,667 INFO: RecommenDev startup [in C:\Users\Christopher\Documents\python\app\__init__.py:37]
2020-08-19 11:24:23,253 INFO: RecommenDev startup [in C:\Users\Christopher\Documents\python\app\__init__.py:37]
2020-08-19 11:27:28,466 INFO: RecommenDev startup [in C:\Users\Christopher\Documents\python\app\__init__.py:37]
2020-08-19 17:35:40,115 INFO: RecommenDev startup [in C:\Users\Christopher\Documents\python\app\__init__.py:37]
2020-08-19 17:36:22,150 INFO: RecommenDev startup [in C:\Users\Christopher\Documents\python\app\__init__.py:37]
2020-08-19 17:36:51,252 ERROR: Exception on /reset_password_request [POST] [in C:\Users\Christopher\miniconda3\envs\py37\lib\site-packages\flask\app.py:1892]
Traceback (most recent call last):
  File "C:\Users\Christopher\miniconda3\envs\py37\lib\site-packages\flask_mail.py", line 492, in send
    message.send(connection)
  File "C:\Users\Christopher\miniconda3\envs\py37\lib\site-packages\flask_mail.py", line 427, in send
    connection.send(self)
  File "C:\Users\Christopher\miniconda3\envs\py37\lib\site-packages\flask_mail.py", line 192, in send
    message.rcpt_options)
  File "C:\Users\Christopher\miniconda3\envs\py37\lib\smtplib.py", line 852, in sendmail
    self.ehlo_or_helo_if_needed()
  File "C:\Users\Christopher\miniconda3\envs\py37\lib\smtplib.py", line 600, in ehlo_or_helo_if_needed
    if not (200 <= self.ehlo()[0] <= 299):
  File "C:\Users\Christopher\miniconda3\envs\py37\lib\smtplib.py", line 440, in ehlo
    self.putcmd(self.ehlo_msg, name or self.local_hostname)
  File "C:\Users\Christopher\miniconda3\envs\py37\lib\smtplib.py", line 367, in putcmd
    self.send(str)
  File "C:\Users\Christopher\miniconda3\envs\py37\lib\smtplib.py", line 359, in send
    raise SMTPServerDisconnected('please run connect() first')
smtplib.SMTPServerDisconnected: please run connect() first

During handling of the above exception, another exception occurred:

Traceback (most recent call last):
  File "C:\Users\Christopher\miniconda3\envs\py37\lib\site-packages\flask\app.py", line 2447, in wsgi_app
    response = self.full_dispatch_request()
  File "C:\Users\Christopher\miniconda3\envs\py37\lib\site-packages\flask\app.py", line 1952, in full_dispatch_request
    rv = self.handle_user_exception(e)
  File "C:\Users\Christopher\miniconda3\envs\py37\lib\site-packages\flask\app.py", line 1821, in handle_user_exception
    reraise(exc_type, exc_value, tb)
  File "C:\Users\Christopher\miniconda3\envs\py37\lib\site-packages\flask\_compat.py", line 39, in reraise
    raise value
  File "C:\Users\Christopher\miniconda3\envs\py37\lib\site-packages\flask\app.py", line 1950, in full_dispatch_request
    rv = self.dispatch_request()
  File "C:\Users\Christopher\miniconda3\envs\py37\lib\site-packages\flask\app.py", line 1936, in dispatch_request
    return self.view_functions[rule.endpoint](**req.view_args)
  File "C:\Users\Christopher\Documents\python\app\routes.py", line 231, in reset_password_request
    send_password_reset_email(user)
  File "C:\Users\Christopher\Documents\python\app\email.py", line 18, in send_password_reset_email
    html_body=render_template('email/reset_password.html', user=user, token=token))
  File "C:\Users\Christopher\Documents\python\app\email.py", line 10, in send_email
    mail.send(msg)
  File "C:\Users\Christopher\miniconda3\envs\py37\lib\site-packages\flask_mail.py", line 492, in send
    message.send(connection)
  File "C:\Users\Christopher\miniconda3\envs\py37\lib\site-packages\flask_mail.py", line 152, in __exit__
    self.host.quit()
  File "C:\Users\Christopher\miniconda3\envs\py37\lib\smtplib.py", line 984, in quit
    res = self.docmd("quit")
  File "C:\Users\Christopher\miniconda3\envs\py37\lib\smtplib.py", line 420, in docmd
    self.putcmd(cmd, args)
  File "C:\Users\Christopher\miniconda3\envs\py37\lib\smtplib.py", line 367, in putcmd
    self.send(str)
  File "C:\Users\Christopher\miniconda3\envs\py37\lib\smtplib.py", line 359, in send
    raise SMTPServerDisconnected('please run connect() first')
smtplib.SMTPServerDisconnected: please run connect() first
2020-08-19 17:41:24,228 INFO: RecommenDev startup [in C:\Users\Christopher\Documents\python\app\__init__.py:37]
